<?xml version="1.0" encoding="UTF-8"?>
<testng-results skipped="0" failed="2" total="5" passed="3">
  <reporter-output>
  </reporter-output>
  <suite name="Default suite" duration-ms="63461" started-at="2017-11-16T11:04:54Z" finished-at="2017-11-16T11:05:58Z">
    <groups>
    </groups>
    <test name="Default test" duration-ms="63461" started-at="2017-11-16T11:04:54Z" finished-at="2017-11-16T11:05:58Z">
      <class name="com.pack.home.TestExecution.TestRun">
        <test-method status="PASS" signature="executing()[pri:0, instance:com.pack.home.TestExecution.TestRun@5e3a8624]" name="executing" is-config="true" duration-ms="8749" started-at="2017-11-16T16:34:54Z" finished-at="2017-11-16T16:35:03Z">
          <reporter-output>
          </reporter-output>
        </test-method> <!-- executing -->
        <test-method status="PASS" signature="login1()[pri:0, instance:com.pack.home.TestExecution.TestRun@5e3a8624]" name="login1" duration-ms="8936" started-at="2017-11-16T16:35:03Z" description="Email cannot be blank (passes)" finished-at="2017-11-16T16:35:12Z">
          <reporter-output>
          </reporter-output>
        </test-method> <!-- login1 -->
        <test-method status="PASS" signature="login2()[pri:0, instance:com.pack.home.TestExecution.TestRun@5e3a8624]" name="login2" duration-ms="10369" started-at="2017-11-16T16:35:12Z" description="Password cannot be blank." finished-at="2017-11-16T16:35:23Z">
          <reporter-output>
          </reporter-output>
        </test-method> <!-- login2 -->
        <test-method status="FAIL" signature="login3()[pri:0, instance:com.pack.home.TestExecution.TestRun@5e3a8624]" name="login3" duration-ms="10482" started-at="2017-11-16T16:35:23Z" description="Performs an unsuccessful login invalid password " finished-at="2017-11-16T16:35:33Z">
          <exception class="java.lang.AssertionError">
            <message>
              <![CDATA[expected [http://69.176.98.99:9356/admin/dashboard] but found [http://69.176.98.99:9356/admin]]]>
            </message>
            <full-stacktrace>
              <![CDATA[java.lang.AssertionError: expected [http://69.176.98.99:9356/admin/dashboard] but found [http://69.176.98.99:9356/admin]
	at org.testng.Assert.fail(Assert.java:94)
	at org.testng.Assert.failNotEquals(Assert.java:494)
	at org.testng.Assert.assertEquals(Assert.java:123)
	at org.testng.Assert.assertEquals(Assert.java:176)
	at org.testng.Assert.assertEquals(Assert.java:186)
	at com.pack.home.TestExecution.TestRun.login3(TestRun.java:51)
	at sun.reflect.NativeMethodAccessorImpl.invoke0(Native Method)
	at sun.reflect.NativeMethodAccessorImpl.invoke(NativeMethodAccessorImpl.java:62)
	at sun.reflect.DelegatingMethodAccessorImpl.invoke(DelegatingMethodAccessorImpl.java:43)
	at java.lang.reflect.Method.invoke(Method.java:498)
	at org.testng.internal.MethodInvocationHelper.invokeMethod(MethodInvocationHelper.java:80)
	at org.testng.internal.Invoker.invokeMethod(Invoker.java:714)
	at org.testng.internal.Invoker.invokeTestMethod(Invoker.java:901)
	at org.testng.internal.Invoker.invokeTestMethods(Invoker.java:1231)
	at org.testng.internal.TestMethodWorker.invokeTestMethods(TestMethodWorker.java:127)
	at org.testng.internal.TestMethodWorker.run(TestMethodWorker.java:111)
	at org.testng.TestRunner.privateRun(TestRunner.java:767)
	at org.testng.TestRunner.run(TestRunner.java:617)
	at org.testng.SuiteRunner.runTest(SuiteRunner.java:334)
	at org.testng.SuiteRunner.runSequentially(SuiteRunner.java:329)
	at org.testng.SuiteRunner.privateRun(SuiteRunner.java:291)
	at org.testng.SuiteRunner.run(SuiteRunner.java:240)
	at org.testng.SuiteRunnerWorker.runSuite(SuiteRunnerWorker.java:52)
	at org.testng.SuiteRunnerWorker.run(SuiteRunnerWorker.java:86)
	at org.testng.TestNG.runSuitesSequentially(TestNG.java:1198)
	at org.testng.TestNG.runSuitesLocally(TestNG.java:1123)
	at org.testng.TestNG.run(TestNG.java:1031)
	at org.testng.remote.AbstractRemoteTestNG.run(AbstractRemoteTestNG.java:114)
	at org.testng.remote.RemoteTestNG.initAndRun(RemoteTestNG.java:251)
	at org.testng.remote.RemoteTestNG.main(RemoteTestNG.java:77)
]]>
            </full-stacktrace>
          </exception> <!-- java.lang.AssertionError -->
          <reporter-output>
          </reporter-output>
        </test-method> <!-- login3 -->
        <test-method status="FAIL" signature="login4()[pri:0, instance:com.pack.home.TestExecution.TestRun@5e3a8624]" name="login4" duration-ms="10301" started-at="2017-11-16T16:35:33Z" description="Performs an unsuccessful login invalid username " finished-at="2017-11-16T16:35:43Z">
          <exception class="java.lang.AssertionError">
            <message>
              <![CDATA[expected [http://69.176.98.99:9356/admin/dashboard] but found [http://69.176.98.99:9356/admin]]]>
            </message>
            <full-stacktrace>
              <![CDATA[java.lang.AssertionError: expected [http://69.176.98.99:9356/admin/dashboard] but found [http://69.176.98.99:9356/admin]
	at org.testng.Assert.fail(Assert.java:94)
	at org.testng.Assert.failNotEquals(Assert.java:494)
	at org.testng.Assert.assertEquals(Assert.java:123)
	at org.testng.Assert.assertEquals(Assert.java:176)
	at org.testng.Assert.assertEquals(Assert.java:186)
	at com.pack.home.TestExecution.TestRun.login4(TestRun.java:60)
	at sun.reflect.NativeMethodAccessorImpl.invoke0(Native Method)
	at sun.reflect.NativeMethodAccessorImpl.invoke(NativeMethodAccessorImpl.java:62)
	at sun.reflect.DelegatingMethodAccessorImpl.invoke(DelegatingMethodAccessorImpl.java:43)
	at java.lang.reflect.Method.invoke(Method.java:498)
	at org.testng.internal.MethodInvocationHelper.invokeMethod(MethodInvocationHelper.java:80)
	at org.testng.internal.Invoker.invokeMethod(Invoker.java:714)
	at org.testng.internal.Invoker.invokeTestMethod(Invoker.java:901)
	at org.testng.internal.Invoker.invokeTestMethods(Invoker.java:1231)
	at org.testng.internal.TestMethodWorker.invokeTestMethods(TestMethodWorker.java:127)
	at org.testng.internal.TestMethodWorker.run(TestMethodWorker.java:111)
	at org.testng.TestRunner.privateRun(TestRunner.java:767)
	at org.testng.TestRunner.run(TestRunner.java:617)
	at org.testng.SuiteRunner.runTest(SuiteRunner.java:334)
	at org.testng.SuiteRunner.runSequentially(SuiteRunner.java:329)
	at org.testng.SuiteRunner.privateRun(SuiteRunner.java:291)
	at org.testng.SuiteRunner.run(SuiteRunner.java:240)
	at org.testng.SuiteRunnerWorker.runSuite(SuiteRunnerWorker.java:52)
	at org.testng.SuiteRunnerWorker.run(SuiteRunnerWorker.java:86)
	at org.testng.TestNG.runSuitesSequentially(TestNG.java:1198)
	at org.testng.TestNG.runSuitesLocally(TestNG.java:1123)
	at org.testng.TestNG.run(TestNG.java:1031)
	at org.testng.remote.AbstractRemoteTestNG.run(AbstractRemoteTestNG.java:114)
	at org.testng.remote.RemoteTestNG.initAndRun(RemoteTestNG.java:251)
	at org.testng.remote.RemoteTestNG.main(RemoteTestNG.java:77)
]]>
            </full-stacktrace>
          </exception> <!-- java.lang.AssertionError -->
          <reporter-output>
          </reporter-output>
        </test-method> <!-- login4 -->
        <test-method status="PASS" signature="login5()[pri:0, instance:com.pack.home.TestExecution.TestRun@5e3a8624]" name="login5" duration-ms="13385" started-at="2017-11-16T16:35:43Z" description="Performs an successful login and checks the dashboard url" finished-at="2017-11-16T16:35:57Z">
          <reporter-output>
          </reporter-output>
        </test-method> <!-- login5 -->
        <test-method status="PASS" signature="afterMethod()[pri:0, instance:com.pack.home.TestExecution.TestRun@5e3a8624]" name="afterMethod" is-config="true" duration-ms="1169" started-at="2017-11-16T16:35:57Z" finished-at="2017-11-16T16:35:58Z">
          <reporter-output>
          </reporter-output>
        </test-method> <!-- afterMethod -->
      </class> <!-- com.pack.home.TestExecution.TestRun -->
    </test> <!-- Default test -->
  </suite> <!-- Default suite -->
</testng-results>
